Workbook

Sheet Source rows
A1: Year | B1: Source type | C1: Source file or page | D1: Region as ECDC prints it | E1: ECDC code (if given) | F1: Cases (human, total) | G1: Assigned NUTS_ID | H1: Region name in project file | I1: Checked | J1: Comment
A2: 2012 | B2: HTML table on ECDC page | C2: Table of cases 2012 | D2: Grad Beograd | F2: 50 | G2: RS110 | H2: Београдска област
A3: 2012 | B3: HTML table on ECDC page | C3: Table of cases 2012 | D3: Juzno-Banatski district | F3: 10 | G3: RS122 | H3: Јужнобанатска област
A4: 2012 | B4: HTML table on ECDC page | C4: Table of cases 2012 | D4: Sremski district | F4: 6 | G4: RS127 | H4: Сремска област
A5: 2012 | B5: HTML table on ECDC page | C5: Table of cases 2012 | D5: Sumadijski district | F5: 1 | G5: RS218 | H5: Шумадијска област
A6: 2012 | B6: HTML table on ECDC page | C6: Table of cases 2012 | D6: Zapadno-Backi district | F6: 1 | G6: RS121 | H6: Западнобачка област
A7: 2013 | B7: HTML table on ECDC page | C7: Table of cases 2013 | D7: Branicevski district | F7: 3 | G7: RS222 | H7: Браничевска област
A8: 2013 | B8: HTML table on ECDC page | C8: Table of cases 2013 | D8: Grad Beograd | F8: 171 | G8: RS110 | H8: Београдска област
A9: 2013 | B9: HTML table on ECDC page | C9: Table of cases 2013 | D9: Jablanicki district | F9: 1 | G9: RS224 | H9: Јабланичка област
A10: 2013 | B10: HTML table on ECDC page | C10: Table of cases 2013 | D10: Juzno-backi district | F10: 20 | G10: RS123 | H10: Јужнобачка област
A11: 2013 | B11: HTML table on ECDC page | C11: Table of cases 2013 | D11: Juzno-banatski district | F11: 48 | G11: RS122 | H11: Јужнобанатска област
A12: 2013 | B12: HTML table on ECDC page | C12: Table of cases 2013 | D12: Kolubarski district | F12: 10 | G12: RS212 | H12: Колубарска област
A13: 2013 | B13: HTML table on ECDC page | C13: Table of cases 2013 | D13: Macvanski district | F13: 6 | G13: RS213 | H13: Мачванска област
... A47: 2016 | B47: XLSX | C47: West-Nile-fever-historical-data-2016_0.xlsx | D47: Sremski | F47: 1 | G47: RS127 | H47: Сремска област
A48: 2017 | B48: XLSX, sheet 1 (human) | C48: Table epi update 2017 WNF.xlsx | D48: Grad Beograd | E48: RSG125373 | F48: 34 | G48: RS110 | H48: Београдска област
A49: 2017 | B49: XLSX, sheet 1 (human) | C49: Table epi update 2017 WNF.xlsx | D49: Juzno-backi | E49: RSG125375 | F49: 2 | G49: RS123 | H49: Јужнобачка област
A50: 2017 | B50: XLSX, sheet 1 (human) | C50: Table epi update 2017 WNF.xlsx | D50: Juzno-banatski | E50: RSG125376 | F50: 5 | G50: RS122 | H50: Јужнобанатска област
A51: 2017 | B51: XLSX, sheet 1 (human) | C51: Table epi update 2017 WNF.xlsx | D51: Podunavski | E51: RSG125387 | F51: 6 | G51: RS227 | H51: Подунавска област
A52: 2017 | B52: XLSX, sheet 1 (human) | C52: Table epi update 2017 WNF.xlsx | D52: Severno-backi | E52: RSG125392 | F52: 1 | G52: RS125 | H52: Севернобачка област
A53: 2017 | B53: XLSX, sheet 1 (human) | C53: Table epi update 2017 WNF.xlsx | D53: Zapadno-backi | E53: RSG125399 | F53: 1 | G53: RS121 | H53: Западнобачка област
A54: 2018 | B54: XLSX | C54: End-of-the season update 2018_table.xlsx | D54: Borski | F54: 1 | G54: RS221 | H54: Борска област
A55: 2018 | B55: XLSX | C55: End-of-the season update 2018_table.xlsx | D55: Branicevski | F55: 21 | G55: RS222 | H55: Браничевска област
A56: 2018 | B56: XLSX | C56: End-of-the season update 2018_table.xlsx | D56: Grad Beograd | F56: 213 | G56: RS110 | H56: Београдска област
A57: 2018 | B57: XLSX | C57: End-of-the season update 2018_table.xlsx | D57: Juzno-backi | F57: 54 | G57: RS123 | H57: Јужнобачка област
A58: 2018 | B58: XLSX | C58: End-of-the season update 2018_table.xlsx | D58: Juzno-banatski | F58: 56 | G58: RS122 | H58: Јужнобанатска област
A59: 2018 | B59: XLSX | C59: End-of-the season update 2018_table.xlsx | D59: Kolubarski | F59: 8 | G59: RS212 | H59: Колубарска област
A60: 2018 | B60: XLSX | C60: End-of-the season update 2018_table.xlsx | D60: Macvanski | F60: 1 | G60: RS213 | H60: Мачванска област
A61: 2018 | B61: XLSX | C61: End-of-the season update 2018_table.xlsx | D61: Podunavski | F61: 20 | G61: RS227 | H61: Подунавска област
A62: 2018 | B62: XLSX | C62: End-of-the season update 2018_table.xlsx | D62: Pomoravski | F62: 3 | G62: RS215 | H62: Поморавска област
A63: 2018 | B63: XLSX | C63: End-of-the season update 2018_table.xlsx | D63: Rasinski | F63: 1 | G63: RS216 | H63: Расинска област
A64: 2018 | B64: XLSX | C64: End-of-the season update 2018_table.xlsx | D64: Raski | F64: 1 | G64: RS217 | H64: Рашка област
A65: 2018 | B65: XLSX | C65: End-of-the season update 2018_table.xlsx | D65: Severno-banatski | F65: 6 | G65: RS124 | H65: Севернобанатска област
... A77: 2019 | B77: XLSX | C77: WNV-end-of-seaon-update.xlsx | D77: Severno-banatski | F77: 1 | G77: RS124 | H77: Севернобанатска област
A78: 2021 | B78: XLSX, GAUL-coded | C78: WNV_June_to_Nov_2021_0.xlsx | D78: Grad Beograd | E78: RSG125373 | F78: 4 | G78: RS110 | H78: Београдска област
A79: 2021 | B79: XLSX, GAUL-coded | C79: WNV_June_to_Nov_2021_0.xlsx | D79: Juzno-backi | E79: RSG125375 | F79: 7 | G79: RS123 | H79: Јужнобачка област
A80: 2021 | B80: XLSX, GAUL-coded | C80: WNV_June_to_Nov_2021_0.xlsx | D80: Juzno-banatski | E80: RSG125376 | F80: 2 | G80: RS122 | H80: Јужнобанатска област
A81: 2021 | B81: XLSX, GAUL-coded | C81: WNV_June_to_Nov_2021_0.xlsx | D81: Severno-banatski | E81: RSG125393 | F81: 1 | G81: RS124 | H81: Севернобанатска област
A82: 2021 | B82: XLSX, GAUL-coded | C82: WNV_June_to_Nov_2021_0.xlsx | D82: Srednje-banatski | E82: RSG125394 | F82: 1 | G82: RS126 | H82: Средњобанатска област
A83: 2021 | B83: XLSX, GAUL-coded | C83: WNV_June_to_Nov_2021_0.xlsx | D83: Sremski | E83: RSG125395 | F83: 3 | G83: RS127 | H83: Сремска област
A84: 2024 | B84: Monthly report, Table 1 | C84: wnv-2024.html (Download Table 1 .csv) | D84: Branicevski | E84: RSG125372 | F84: 1 | G84: RS222 | H84: Браничевска област
...

Sheet Region summary
A1: NUTS_ID | B1: Region | C1: 2012 | D1: 2013 | E1: 2014 | F1: 2015 | G1: 2016 | H1: 2017 | I1: 2018 | J1: 2019 | K1: 2021 | L1: 2024 | M1: Total | N1: First invasion year
A2: RS110 | B2: Београдска област | C2: =SUMIFS('Source rows'!$F$2:$F$97,'Source rows'!$G$2:$G$97,$A2,'Source rows'!$A$2:$A$97,C$1+0) -> 50 | D2: =SUMIFS('Source rows'!$F$2:$F$97,'Source rows'!$G$2:$G$97,$A2,'Source rows'!$A$2:$A$97,D$1+0) -> 171 | E2: =SUMIFS('Source rows'!$F$2:$F$97,'Source rows'!$G$2:$G$97,$A2,'Source rows'!$A$2:$A$97,E$1+0) -> 35 | F2: =SUMIFS('Source rows'!$F$2:$F$97,'Source rows'!$G$2:$G$97,$A2,'Source rows'!$A$2:$A$97,F$1+0) -> 15 | G2: =SUMIFS('Source rows'!$F$2:$F$97,'Source rows'!$G$2:$G$97,$A2,'Source rows'!$A$2:$A$97,G$1+0) -> 23 | H2: =SUMIFS('Source rows'!$F$2:$F$97,'Source rows'!$G$2:$G$97,$A2,'Source rows'!$A$2:$A$97,H$1+0) -> 34 | I2: =SUMIFS('Source rows'!$F$2:$F$97,'Source rows'!$G$2:$G$97,$A2,'Source rows'!$A$2:$A$97,I$1+0) -> 213 | J2: =SUMIFS('Source rows'!$F$2:$F$97,'Source rows'!$G$2:$G$97,$A2,'Source rows'!$A$2:$A$97,J$1+0) -> 20 | ... L2: =SUMIFS('Source rows'!$F$2:$F$97,'Source rows'!$G$2:$G$97,$A2,'Source rows'!$A$2:$A$97,L$1+0) -> 21 | M2: =SUM(C2:L2) -> 586 | N2: =IF(M2=0,"never reported",_xlfn.MINIFS('Source rows'!$A$2:$A$97,'Source rows'!$G$2:$G$97,$A2,'Source rows'!$F$2:$F$97,">0")) -> 2012
A3: RS121 | B3: Западнобачка област | C3: =SUMIFS('Source rows'!$F$2:$F$97,'Source rows'!$G$2:$G$97,$A3,'Source rows'!$A$2:$A$97,C$1+0) -> 1 | D3: =SUMIFS('Source rows'!$F$2:$F$97,'Source rows'!$G$2:$G$97,$A3,'Source rows'!$A$2:$A$97,D$1+0) -> 1 | E3: =SUMIFS('Source rows'!$F$2:$F$97,'Source rows'!$G$2:$G$97,$A3,'Source rows'!$A$2:$A$97,E$1+0) -> 0 | F3: =SUMIFS('Source rows'!$F$2:$F$97,'Source rows'!$G$2:$G$97,$A3,'Source rows'!$A$2:$A$97,F$1+0) -> 0 | G3: =SUMIFS('Source rows'!$F$2:$F$97,'Source rows'!$G$2:$G$97,$A3,'Source rows'!$A$2:$A$97,G$1+0) -> 0 | H3: =SUMIFS('Source rows'!$F$2:$F$97,'Source rows'!$G$2:$G$97,$A3,'Source rows'!$A$2:$A$97,H$1+0) -> 1 | I3: =SUMIFS('Source rows'!$F$2:$F$97,'Source rows'!$G$2:$G$97,$A3,'Source rows'!$A$2:$A$97,I$1+0) -> 7 | J3: =SUMIFS('Source rows'!$F$2:$F$97,'Source rows'!$G$2:$G$97,$A3,'Source rows'!$A$2:$A$97,J$1+0) -> 0 | ... L3: =SUMIFS('Source rows'!$F$2:$F$97,'Source rows'!$G$2:$G$97,$A3,'Source rows'!$A$2:$A$97,L$1+0) -> 2 | M3: =SUM(C3:L3) -> 12 | N3: =IF(M3=0,"never reported",_xlfn.MINIFS('Source rows'!$A$2:$A$97,'Source rows'!$G$2:$G$97,$A3,'Source rows'!$F$2:$F$97,">0")) -> 2012
A4: RS122 | B4: Јужнобанатска област | C4: =SUMIFS('Source rows'!$F$2:$F$97,'Source rows'!$G$2:$G$97,$A4,'Source rows'!$A$2:$A$97,C$1+0) -> 10 | D4: =SUMIFS('Source rows'!$F$2:$F$97,'Source rows'!$G$2:$G$97,$A4,'Source rows'!$A$2:$A$97,D$1+0) -> 48 | E4: =SUMIFS('Source rows'!$F$2:$F$97,'Source rows'!$G$2:$G$97,$A4,'Source rows'!$A$2:$A$97,E$1+0) -> 19 | F4: =SUMIFS('Source rows'!$F$2:$F$97,'Source rows'!$G$2:$G$97,$A4,'Source rows'!$A$2:$A$97,F$1+0) -> 7 | G4: =SUMIFS('Source rows'!$F$2:$F$97,'Source rows'!$G$2:$G$97,$A4,'Source rows'!$A$2:$A$97,G$1+0) -> 6 | H4: =SUMIFS('Source rows'!$F$2:$F$97,'Source rows'!$G$2:$G$97,$A4,'Source rows'!$A$2:$A$97,H$1+0) -> 5 | I4: =SUMIFS('Source rows'!$F$2:$F$97,'Source rows'!$G$2:$G$97,$A4,'Source rows'!$A$2:$A$97,I$1+0) -> 56 | J4: =SUMIFS('Source rows'!$F$2:$F$97,'Source rows'!$G$2:$G$97,$A4,'Source rows'!$A$2:$A$97,J$1+0) -> 2 | ... L4: =SUMIFS('Source rows'!$F$2:$F$97,'Source rows'!$G$2:$G$97,$A4,'Source rows'!$A$2:$A$97,L$1+0) -> 5 | M4: =SUM(C4:L4) -> 160 | N4: =IF(M4=0,"never reported",_xlfn.MINIFS('Source rows'!$A$2:$A$97,'Source rows'!$G$2:$G$97,$A4,'Source rows'!$F$2:$F$97,">0")) -> 2012
A5: RS123 | B5: Јужнобачка област | C5: =SUMIFS('Source rows'!$F$2:$F$97,'Source rows'!$G$2:$G$97,$A5,'Source rows'!$A$2:$A$97,C$1+0) -> 0 | D5: =SUMIFS('Source rows'!$F$2:$F$97,'Source rows'!$G$2:$G$97,$A5,'Source rows'!$A$2:$A$97,D$1+0) -> 20 | E5: =SUMIFS('Source rows'!$F$2:$F$97,'Source rows'!$G$2:$G$97,$A5,'Source rows'!$A$2:$A$97,E$1+0) -> 5 | F5: =SUMIFS('Source rows'!$F$2:$F$97,'Source rows'!$G$2:$G$97,$A5,'Source rows'!$A$2:$A$97,F$1+0) -> 2 | G5: =SUMIFS('Source rows'!$F$2:$F$97,'Source rows'!$G$2:$G$97,$A5,'Source rows'!$A$2:$A$97,G$1+0) -> 4 | H5: =SUMIFS('Source rows'!$F$2:$F$97,'Source rows'!$G$2:$G$97,$A5,'Source rows'!$A$2:$A$97,H$1+0) -> 2 | I5: =SUMIFS('Source rows'!$F$2:$F$97,'Source rows'!$G$2:$G$97,$A5,'Source rows'!$A$2:$A$97,I$1+0) -> 54 | J5: =SUMIFS('Source rows'!$F$2:$F$97,'Source rows'!$G$2:$G$97,$A5,'Source rows'!$A$2:$A$97,J$1+0) -> 0 | ... L5: =SUMIFS('Source rows'!$F$2:$F$97,'Source rows'!$G$2:$G$97,$A5,'Source rows'!$A$2:$A$97,L$1+0) -> 9 | M5: =SUM(C5:L5) -> 103 | N5: =IF(M5=0,"never reported",_xlfn.MINIFS('Source rows'!$A$2:$A$97,'Source rows'!$G$2:$G$97,$A5,'Source rows'!$F$2:$F$97,">0")) -> 2013
A6: RS124 | B6: Севернобанатска област | C6: =SUMIFS('Source rows'!$F$2:$F$97,'Source rows'!$G$2:$G$97,$A6,'Source rows'!$A$2:$A$97,C$1+0) -> 0 | D6: =SUMIFS('Source rows'!$F$2:$F$97,'Source rows'!$G$2:$G$97,$A6,'Source rows'!$A$2:$A$97,D$1+0) -> 1 | E6: =SUMIFS('Source rows'!$F$2:$F$97,'Source rows'!$G$2:$G$97,$A6,'Source rows'!$A$2:$A$97,E$1+0) -> 0 | F6: =SUMIFS('Source rows'!$F$2:$F$97,'Source rows'!$G$2:$G$97,$A6,'Source rows'!$A$2:$A$97,F$1+0) -> 0 | G6: =SUMIFS('Source rows'!$F$2:$F$97,'Source rows'!$G$2:$G$97,$A6,'Source rows'!$A$2:$A$97,G$1+0) -> 0 | H6: =SUMIFS('Source rows'!$F$2:$F$97,'Source rows'!$G$2:$G$97,$A6,'Source rows'!$A$2:$A$97,H$1+0) -> 0 | I6: =SUMIFS('Source rows'!$F$2:$F$97,'Source rows'!$G$2:$G$97,$A6,'Source rows'!$A$2:$A$97,I$1+0) -> 6 | J6: =SUMIFS('Source rows'!$F$2:$F$97,'Source rows'!$G$2:$G$97,$A6,'Source rows'!$A$2:$A$97,J$1+0) -> 1 | ... L6: =SUMIFS('Source rows'!$F$2:$F$97,'Source rows'!$G$2:$G$97,$A6,'Source rows'!$A$2:$A$97,L$1+0) -> 2 | M6: =SUM(C6:L6) -> 11 | N6: =IF(M6=0,"never reported",_xlfn.MINIFS('Source rows'!$A$2:$A$97,'Source rows'!$G$2:$G$97,$A6,'Source rows'!$F$2:$F$97,">0")) -> 2013
A7: RS125 | B7: Севернобачка област | C7: =SUMIFS('Source rows'!$F$2:$F$97,'Source rows'!$G$2:$G$97,$A7,'Source rows'!$A$2:$A$97,C$1+0) -> 0 | D7: =SUMIFS('Source rows'!$F$2:$F$97,'Source rows'!$G$2:$G$97,$A7,'Source rows'!$A$2:$A$97,D$1+0) -> 3 | E7: =SUMIFS('Source rows'!$F$2:$F$97,'Source rows'!$G$2:$G$97,$A7,'Source rows'!$A$2:$A$97,E$1+0) -> 0 | F7: =SUMIFS('Source rows'!$F$2:$F$97,'Source rows'!$G$2:$G$97,$A7,'Source rows'!$A$2:$A$97,F$1+0) -> 0 | G7: =SUMIFS('Source rows'!$F$2:$F$97,'Source rows'!$G$2:$G$97,$A7,'Source rows'!$A$2:$A$97,G$1+0) -> 0 | H7: =SUMIFS('Source rows'!$F$2:$F$97,'Source rows'!$G$2:$G$97,$A7,'Source rows'!$A$2:$A$97,H$1+0) -> 1 | I7: =SUMIFS('Source rows'!$F$2:$F$97,'Source rows'!$G$2:$G$97,$A7,'Source rows'!$A$2:$A$97,I$1+0) -> 0 | J7: =SUMIFS('Source rows'!$F$2:$F$97,'Source rows'!$G$2:$G$97,$A7,'Source rows'!$A$2:$A$97,J$1+0) -> 1 | ... L7: =SUMIFS('Source rows'!$F$2:$F$97,'Source rows'!$G$2:$G$97,$A7,'Source rows'!$A$2:$A$97,L$1+0) -> 2 | M7: =SUM(C7:L7) -> 7 | N7: =IF(M7=0,"never reported",_xlfn.MINIFS('Source rows'!$A$2:$A$97,'Source rows'!$G$2:$G$97,$A7,'Source rows'!$F$2:$F$97,">0")) -> 2013
A8: RS126 | B8: Средњобанатска област | C8: =SUMIFS('Source rows'!$F$2:$F$97,'Source rows'!$G$2:$G$97,$A8,'Source rows'!$A$2:$A$97,C$1+0) -> 0 | D8: =SUMIFS('Source rows'!$F$2:$F$97,'Source rows'!$G$2:$G$97,$A8,'Source rows'!$A$2:$A$97,D$1+0) -> 6 | E8: =SUMIFS('Source rows'!$F$2:$F$97,'Source rows'!$G$2:$G$97,$A8,'Source rows'!$A$2:$A$97,E$1+0) -> 0 | F8: =SUMIFS('Source rows'!$F$2:$F$97,'Source rows'!$G$2:$G$97,$A8,'Source rows'!$A$2:$A$97,F$1+0) -> 0 | G8: =SUMIFS('Source rows'!$F$2:$F$97,'Source rows'!$G$2:$G$97,$A8,'Source rows'!$A$2:$A$97,G$1+0) -> 1 | H8: =SUMIFS('Source rows'!$F$2:$F$97,'Source rows'!$G$2:$G$97,$A8,'Source rows'!$A$2:$A$97,H$1+0) -> 0 | I8: =SUMIFS('Source rows'!$F$2:$F$97,'Source rows'!$G$2:$G$97,$A8,'Source rows'!$A$2:$A$97,I$1+0) -> 5 | J8: =SUMIFS('Source rows'!$F$2:$F$97,'Source rows'!$G$2:$G$97,$A8,'Source rows'!$A$2:$A$97,J$1+0) -> 0 | ... L8: =SUMIFS('Source rows'!$F$2:$F$97,'Source rows'!$G$2:$G$97,$A8,'Source rows'!$A$2:$A$97,L$1+0) -> 3 | M8: =SUM(C8:L8) -> 16 | N8: =IF(M8=0,"never reported",_xlfn.MINIFS('Source rows'!$A$2:$A$97,'Source rows'!$G$2:$G$97,$A8,'Source rows'!$F$2:$F$97,">0")) -> 2013
A9: RS127 | B9: Сремска област | C9: =SUMIFS('Source rows'!$F$2:$F$97,'Source rows'!$G$2:$G$97,$A9,'Source rows'!$A$2:$A$97,C$1+0) -> 6 | D9: =SUMIFS('Source rows'!$F$2:$F$97,'Source rows'!$G$2:$G$97,$A9,'Source rows'!$A$2:$A$97,D$1+0) -> 11 | E9: =SUMIFS('Source rows'!$F$2:$F$97,'Source rows'!$G$2:$G$97,$A9,'Source rows'!$A$2:$A$97,E$1+0) -> 6 | F9: =SUMIFS('Source rows'!$F$2:$F$97,'Source rows'!$G$2:$G$97,$A9,'Source rows'!$A$2:$A$97,F$1+0) -> 1 | G9: =SUMIFS('Source rows'!$F$2:$F$97,'Source rows'!$G$2:$G$97,$A9,'Source rows'!$A$2:$A$97,G$1+0) -> 1 | H9: =SUMIFS('Source rows'!$F$2:$F$97,'Source rows'!$G$2:$G$97,$A9,'Source rows'!$A$2:$A$97,H$1+0) -> 0 | I9: =SUMIFS('Source rows'!$F$2:$F$97,'Source rows'!$G$2:$G$97,$A9,'Source rows'!$A$2:$A$97,I$1+0) -> 14 | J9: =SUMIFS('Source rows'!$F$2:$F$97,'Source rows'!$G$2:$G$97,$A9,'Source rows'!$A$2:$A$97,J$1+0) -> 0 | ... L9: =SUMIFS('Source rows'!$F$2:$F$97,'Source rows'!$G$2:$G$97,$A9,'Source rows'!$A$2:$A$97,L$1+0) -> 3 | M9: =SUM(C9:L9) -> 45 | N9: =IF(M9=0,"never reported",_xlfn.MINIFS('Source rows'!$A$2:$A$97,'Source rows'!$G$2:$G$97,$A9,'Source rows'!$F$2:$F$97,">0")) -> 2012
A10: RS211 | B10: Златиборска област | C10: =SUMIFS('Source rows'!$F$2:$F$97,'Source rows'!$G$2:$G$97,$A10,'Source rows'!$A$2:$A$97,C$1+0) -> 0 | D10: =SUMIFS('Source rows'!$F$2:$F$97,'Source rows'!$G$2:$G$97,$A10,'Source rows'!$A$2:$A$97,D$1+0) -> 1 | E10: =SUMIFS('Source rows'!$F$2:$F$97,'Source rows'!$G$2:$G$97,$A10,'Source rows'!$A$2:$A$97,E$1+0) -> 0 | F10: =SUMIFS('Source rows'!$F$2:$F$97,'Source rows'!$G$2:$G$97,$A10,'Source rows'!$A$2:$A$97,F$1+0) -> 0 | G10: =SUMIFS('Source rows'!$F$2:$F$97,'Source rows'!$G$2:$G$97,$A10,'Source rows'!$A$2:$A$97,G$1+0) -> 0 | H10: =SUMIFS('Source rows'!$F$2:$F$97,'Source rows'!$G$2:$G$97,$A10,'Source rows'!$A$2:$A$97,H$1+0) -> 0 | I10: =SUMIFS('Source rows'!$F$2:$F$97,'Source rows'!$G$2:$G$97,$A10,'Source rows'!$A$2:$A$97,I$1+0) -> 2 | J10: =SUMIFS('Source rows'!$F$2:$F$97,'Source rows'!$G$2:$G$97,$A10,'Source rows'!$A$2:$A$97,J$1+0) -> 0 | ... L10: =SUMIFS('Source rows'!$F$2:$F$97,'Source rows'!$G$2:$G$97,$A10,'Source rows'!$A$2:$A$97,L$1+0) -> 0 | M10: =SUM(C10:L10) -> 3 | N10: =IF(M10=0,"never reported",_xlfn.MINIFS('Source rows'!$A$2:$A$97,'Source rows'!$G$2:$G$97,$A10,'Source rows'!$F$2:$F$97,">0")) -> 2013
A11: RS212 | B11: Колубарска област | C11: =SUMIFS('Source rows'!$F$2:$F$97,'Source rows'!$G$2:$G$97,$A11,'Source rows'!$A$2:$A$97,C$1+0) -> 0 | D11: =SUMIFS('Source rows'!$F$2:$F$97,'Source rows'!$G$2:$G$97,$A11,'Source rows'!$A$2:$A$97,D$1+0) -> 10 | E11: =SUMIFS('Source rows'!$F$2:$F$97,'Source rows'!$G$2:$G$97,$A11,'Source rows'!$A$2:$A$97,E$1+0) -> 4 | F11: =SUMIFS('Source rows'!$F$2:$F$97,'Source rows'!$G$2:$G$97,$A11,'Source rows'!$A$2:$A$97,F$1+0) -> 1 | G11: =SUMIFS('Source rows'!$F$2:$F$97,'Source rows'!$G$2:$G$97,$A11,'Source rows'!$A$2:$A$97,G$1+0) -> 0 | H11: =SUMIFS('Source rows'!$F$2:$F$97,'Source rows'!$G$2:$G$97,$A11,'Source rows'!$A$2:$A$97,H$1+0) -> 0 | I11: =SUMIFS('Source rows'!$F$2:$F$97,'Source rows'!$G$2:$G$97,$A11,'Source rows'!$A$2:$A$97,I$1+0) -> 8 | J11: =SUMIFS('Source rows'!$F$2:$F$97,'Source rows'!$G$2:$G$97,$A11,'Source rows'!$A$2:$A$97,J$1+0) -> 1 | ... L11: =SUMIFS('Source rows'!$F$2:$F$97,'Source rows'!$G$2:$G$97,$A11,'Source rows'!$A$2:$A$97,L$1+0) -> 0 | M11: =SUM(C11:L11) -> 24 | N11: =IF(M11=0,"never reported",_xlfn.MINIFS('Source rows'!$A$2:$A$97,'Source rows'!$G$2:$G$97,$A11,'Source rows'!$F$2:$F$97,">0")) -> 2013
A12: RS213 | B12: Мачванска област | C12: =SUMIFS('Source rows'!$F$2:$F$97,'Source rows'!$G$2:$G$97,$A12,'Source rows'!$A$2:$A$97,C$1+0) -> 0 | D12: =SUMIFS('Source rows'!$F$2:$F$97,'Source rows'!$G$2:$G$97,$A12,'Source rows'!$A$2:$A$97,D$1+0) -> 6 | E12: =SUMIFS('Source rows'!$F$2:$F$97,'Source rows'!$G$2:$G$97,$A12,'Source rows'!$A$2:$A$97,E$1+0) -> 0 | F12: =SUMIFS('Source rows'!$F$2:$F$97,'Source rows'!$G$2:$G$97,$A12,'Source rows'!$A$2:$A$97,F$1+0) -> 1 | G12: =SUMIFS('Source rows'!$F$2:$F$97,'Source rows'!$G$2:$G$97,$A12,'Source rows'!$A$2:$A$97,G$1+0) -> 1 | H12: =SUMIFS('Source rows'!$F$2:$F$97,'Source rows'!$G$2:$G$97,$A12,'Source rows'!$A$2:$A$97,H$1+0) -> 0 | I12: =SUMIFS('Source rows'!$F$2:$F$97,'Source rows'!$G$2:$G$97,$A12,'Source rows'!$A$2:$A$97,I$1+0) -> 1 | J12: =SUMIFS('Source rows'!$F$2:$F$97,'Source rows'!$G$2:$G$97,$A12,'Source rows'!$A$2:$A$97,J$1+0) -> 0 | ... L12: =SUMIFS('Source rows'!$F$2:$F$97,'Source rows'!$G$2:$G$97,$A12,'Source rows'!$A$2:$A$97,L$1+0) -> 4 | M12: =SUM(C12:L12) -> 13 | N12: =IF(M12=0,"never reported",_xlfn.MINIFS('Source rows'!$A$2:$A$97,'Source rows'!$G$2:$G$97,$A12,'Source rows'!$F$2:$F$97,">0")) -> 2013
A13: RS214 | B13: Моравичка област | C13: =SUMIFS('Source rows'!$F$2:$F$97,'Source rows'!$G$2:$G$97,$A13,'Source rows'!$A$2:$A$97,C$1+0) -> 0 | D13: =SUMIFS('Source rows'!$F$2:$F$97,'Source rows'!$G$2:$G$97,$A13,'Source rows'!$A$2:$A$97,D$1+0) -> 2 | E13: =SUMIFS('Source rows'!$F$2:$F$97,'Source rows'!$G$2:$G$97,$A13,'Source rows'!$A$2:$A$97,E$1+0) -> 0 | F13: =SUMIFS('Source rows'!$F$2:$F$97,'Source rows'!$G$2:$G$97,$A13,'Source rows'!$A$2:$A$97,F$1+0) -> 0 | G13: =SUMIFS('Source rows'!$F$2:$F$97,'Source rows'!$G$2:$G$97,$A13,'Source rows'!$A$2:$A$97,G$1+0) -> 0 | H13: =SUMIFS('Source rows'!$F$2:$F$97,'Source rows'!$G$2:$G$97,$A13,'Source rows'!$A$2:$A$97,H$1+0) -> 0 | I13: =SUMIFS('Source rows'!$F$2:$F$97,'Source rows'!$G$2:$G$97,$A13,'Source rows'!$A$2:$A$97,I$1+0) -> 0 | J13: =SUMIFS('Source rows'!$F$2:$F$97,'Source rows'!$G$2:$G$97,$A13,'Source rows'!$A$2:$A$97,J$1+0) -> 0 | ... L13: =SUMIFS('Source rows'!$F$2:$F$97,'Source rows'!$G$2:$G$97,$A13,'Source rows'!$A$2:$A$97,L$1+0) -> 0 | M13: =SUM(C13:L13) -> 2 | N13: =IF(M13=0,"never reported",_xlfn.MINIFS('Source rows'!$A$2:$A$97,'Source rows'!$G$2:$G$97,$A13,'Source rows'!$F$2:$F$97,">0")) -> 2013
... A26: RS229 | B26: Топличка област | C26: =SUMIFS('Source rows'!$F$2:$F$97,'Source rows'!$G$2:$G$97,$A26,'Source rows'!$A$2:$A$97,C$1+0) -> 0 | D26: =SUMIFS('Source rows'!$F$2:$F$97,'Source rows'!$G$2:$G$97,$A26,'Source rows'!$A$2:$A$97,D$1+0) -> 0 | E26: =SUMIFS('Source rows'!$F$2:$F$97,'Source rows'!$G$2:$G$97,$A26,'Source rows'!$A$2:$A$97,E$1+0) -> 0 | F26: =SUMIFS('Source rows'!$F$2:$F$97,'Source rows'!$G$2:$G$97,$A26,'Source rows'!$A$2:$A$97,F$1+0) -> 0 | G26: =SUMIFS('Source rows'!$F$2:$F$97,'Source rows'!$G$2:$G$97,$A26,'Source rows'!$A$2:$A$97,G$1+0) -> 0 | H26: =SUMIFS('Source rows'!$F$2:$F$97,'Source rows'!$G$2:$G$97,$A26,'Source rows'!$A$2:$A$97,H$1+0) -> 0 | I26: =SUMIFS('Source rows'!$F$2:$F$97,'Source rows'!$G$2:$G$97,$A26,'Source rows'!$A$2:$A$97,I$1+0) -> 0 | J26: =SUMIFS('Source rows'!$F$2:$F$97,'Source rows'!$G$2:$G$97,$A26,'Source rows'!$A$2:$A$97,J$1+0) -> 0 | ... L26: =SUMIFS('Source rows'!$F$2:$F$97,'Source rows'!$G$2:$G$97,$A26,'Source rows'!$A$2:$A$97,L$1+0) -> 0 | M26: =SUM(C26:L26) -> 0 | N26: =IF(M26=0,"never reported",_xlfn.MINIFS('Source rows'!$A$2:$A$97,'Source rows'!$G$2:$G$97,$A26,'Source rows'!$F$2:$F$97,">0")) -> never reported
A28: Both columns are computed from 'Source rows', so a correction there flows through. First invasion year is the earliest season in which the region reported at least one human case.

Sheet Sources and gaps
A1: Season | B1: Status | C1: Source type | D1: File or page | E1: URL | F1: Serbian regions | G1: Note
A2: 2011 | B2: checked, Serbia absent | C2: HTML table on ECDC page | D2: Table of cases 2011 | E2: https://www.ecdc.europa.eu/en/publications-data/table-transmission-west-nile-fever-may-november-2011-table-cases-2011 | F2: 0 | G2: Serbia does not appear; Albania (Lezhe) and North Macedonia (Skopje) do. Absence claim, worth your own look.
A3: 2012 | B3: transcribed | C3: HTML table on ECDC page | D3: Table of cases 2012 | E3: https://www.ecdc.europa.eu/en/publications-data/table-transmission-west-nile-fever-may-november-2012-table-cases-2012 | F3: 5 | G3: One further Serbian case has area 'N/A' and was not assigned to any region.
A4: 2013 | B4: transcribed | C4: HTML table on ECDC page | D4: Table of cases 2013 | E4: https://www.ecdc.europa.eu/en/publications-data/table-transmission-west-nile-fever-may-november-2013-table-cases-2013 | F4: 18 | G4: Largest season; also lists Bosnia and Herzegovina and Montenegro.
A5: 2014 | B5: transcribed | C5: HTML table on ECDC page | D5: Table of cases 2014 | E5: https://www.ecdc.europa.eu/en/publications-data/table-transmission-west-nile-fever-may-november-2014-table-cases-2014 | F5: 9
A6: 2015 | B6: transcribed | C6: HTML table on ECDC page | D6: Table of cases 2015 | E6: https://www.ecdc.europa.eu/en/publications-data/table-transmission-west-nile-fever-may-november-2015-table-cases-2015 | F6: 7
A7: 2016 | B7: transcribed | C7: XLSX | D7: West-Nile-fever-historical-data-2016_0.xlsx | E7: https://www.ecdc.europa.eu/en/sites/default/files/documents/West-Nile-fever-historical-data-2016_0.xlsx | F7: 7
A8: 2017 | B8: transcribed | C8: XLSX, sheet 1 (human) | D8: Table epi update 2017 WNF.xlsx | E8: https://www.ecdc.europa.eu/en/sites/default/files/documents/Table%20epi%20update%202017%20WNF.xlsx | F8: 6 | G8: Human cases are on sheet 1; sheet 2 is equine. The page text mentions only equine.
A9: 2018 | B9: transcribed | C9: XLSX | D9: End-of-the season update 2018_table.xlsx | E9: https://www.ecdc.europa.eu/en/sites/default/files/documents/End-of-the%20season%20update%202018_table.xlsx | F9: 17 | G9: Kosovo (Kosovski, 14 cases) also appears and is not yet in the assembled file.
A10: 2019 | B10: transcribed | C10: XLSX | D10: WNV-end-of-seaon-update.xlsx | E10: https://www.ecdc.europa.eu/en/sites/default/files/documents/WNV-end-of-seaon-update.xlsx | F10: 7 | G10: North Macedonia (Jugozapaden, Skopski) also appears.
A11: 2020 | B11: checked, no Serbian section | C11: XLSX | D11: west-nile-virus-july-to december-2020-transmission-season.xlsx | E11: https://www.ecdc.europa.eu/en/sites/default/files/documents/west-nile-virus-july-to%20december-2020-transmission-season.xlsx | F11: 0 | G11: Absence claim, worth your own look.
A12: 2021 | B12: transcribed | C12: XLSX, GAUL-coded | D12: WNV_June_to_Nov_2021_0.xlsx | E12: https://www.ecdc.europa.eu/en/sites/default/files/documents/WNV_June_to_Nov_2021_0.xlsx | F12: 6 | G12: Regions carry GAUL codes; names agree with the codes.
A13: 2022 | B13: no tabular source located | F13: 0 | G13: Publication page carries a map image only.
A14: 2023 | B14: no tabular source located | F14: 0 | G14: Publication page carries a map image only.
A15: 2024 | B15: transcribed | C15: Monthly report, Table 1 | D15: wnv-2024.html (Download Table 1 .csv) | E15: https://wnv-monthly.ecdc.europa.eu/archive/wnv-2024.html | F15: 14 | G15: Kosovo, North Macedonia, Albania and Türkiye also reported at region level.
A17: Index of all seasons: https://www.ecdc.europa.eu/en/west-nile-fever/surveillance-and-disease-data/historical
A18: Column checked in every source: 'Number of human cases' (total reported), not the confirmed-only column, matching the convention of the counts already in WNV_NUTS3cases_2006to2025.csv.
A19: Nothing subnational exists before 2011. Serbian regions therefore enter the at-risk set at 2012 by delayed entry.
