Workbook

Sheet Source rows
A1: Year | B1: Country | C1: Source | D1: Region as ECDC prints it | E1: ECDC code (if given) | F1: Cases (human, total) | G1: Assigned unit | H1: Unit name | I1: Mapping confidence | J1: Basis of mapping | K1: Checked | L1: Comment
A2: 2011 | B2: AL | C2: Table of cases 2011 (HTML) | D2: Lezhe prefecture | F2: 2 | G2: AL014 | H2: Lezhë | I2: certain | J2: prefecture named directly
A3: 2011 | B3: MK | C3: Table of cases 2011 (HTML) | D3: Skopje region | F3: 4 | G3: MK008 | H3: Скопски | I3: certain
A4: 2012 | B4: MK | C4: Table of cases 2012 (HTML) | D4: Krusevo municipality | F4: 1 | G4: MK005 | H4: Пелагониски | I4: assigned | J4: Kruševo lies in the Pelagonia region
A5: 2012 | B5: MK | C5: Table of cases 2012 (HTML) | D5: Lipkovo municipality | F5: 1 | G5: MK007 | H5: Североисточен | I5: assigned | J5: Lipkovo lies in the Northeastern region
A6: 2012 | B6: MK | C6: Table of cases 2012 (HTML) | D6: Skopje region | F6: 3 | G6: MK008 | H6: Скопски | I6: certain
A7: 2012 | B7: MK | C7: Table of cases 2012 (HTML) | D7: Struga municipality | F7: 1 | G7: MK003 | H7: Југозападен | I7: assigned | J7: Struga lies in the Southwestern region
A8: 2012 | B8: XK | C8: Table of cases 2012 (HTML) | D8: Kosovski region (Pristina) | F8: 2 | G8: XK001 | H8: Prishtinë | I8: certain
A9: 2012 | B9: XK | C9: Table of cases 2012 (HTML) | D9: Kosovsko-Pomoravski region | F9: 1 | G9: XK006 | H9: Gjilan | I9: uncertain | J9: read as the Gjilan region; confirm before use
A10: 2012 | B10: XK | C10: Table of cases 2012 (HTML) | D10: Prizremski region | F10: 1 | G10: XK004 | H10: Prizren | I10: certain
A11: 2012 | B11: ME | C11: Table of cases 2012 (HTML) | D11: Podgorica or Ulcinj region | F11: 1 | G11: ME000 | H11: Црна Гора | I11: certain | J11: Montenegro is a single unit
A12: 2013 | B12: MK | C12: Table of cases 2013 (HTML) | D12: Istocen | F12: 1 | G12: MK002 | H12: Источен | I12: certain
A13: 2013 | B13: ME | C13: Table of cases 2013 (HTML) | D13: Cetinje region | F13: 1 | G13: ME000 | H13: Црна Гора | I13: certain | J13: Montenegro is a single unit
A14: 2013 | B14: ME | C14: Table of cases 2013 (HTML) | D14: Podgorica or Bar region | F14: 1 | G14: ME000 | H14: Црна Гора | I14: certain | J14: Montenegro is a single unit
A15: 2013 | B15: ME | C15: Table of cases 2013 (HTML) | D15: Podgorica | F15: 2 | G15: ME000 | H15: Црна Гора | I15: certain | J15: Montenegro is a single unit
A16: 2018 | B16: XK | C16: End-of-the season update 2018_table.xlsx | D16: Kosovski | F16: 14 | G16: XK001 | H16: Prishtinë | I16: certain
A17: 2019 | B17: MK | C17: WNV-end-of-seaon-update.xlsx | D17: Jugozapaden | F17: 1 | G17: MK003 | H17: Југозападен | I17: certain
A18: 2019 | B18: MK | C18: WNV-end-of-seaon-update.xlsx | D18: Skopski | F18: 5 | G18: MK008 | H18: Скопски | I18: certain
A19: 2024 | B19: XK | C19: wnv-2024.html, Table 1 | D19: Prishtinë | E19: XK001 | F19: 2 | G19: XK001 | H19: Prishtinë | I19: certain
A20: 2024 | B20: XK | C20: wnv-2024.html, Table 1 | D20: Mitrovicë | E20: XK002 | F20: 1 | G20: XK002 | H20: Mitrovicë | I20: certain
A21: 2024 | B21: XK | C21: wnv-2024.html, Table 1 | D21: Prizren | E21: XK004 | F21: 1 | G21: XK004 | H21: Prizren | I21: certain
A22: 2024 | B22: MK | C22: wnv-2024.html, Table 1 | D22: Jugoistočen | E22: MK004 | F22: 1 | G22: MK004 | H22: Југоисточен | I22: certain
A23: 2024 | B23: MK | C23: wnv-2024.html, Table 1 | D23: Pološki | E23: MK006 | F23: 1 | G23: MK006 | H23: Полошки | I23: certain
A24: 2024 | B24: AL | C24: wnv-2024.html, Table 1 | D24: Berat | E24: ALG1305 | F24: 14 | G24: AL031 | H24: Berat | I24: assigned | J24: district to prefecture
A25: 2024 | B25: AL | C25: wnv-2024.html, Table 1 | D25: Durres | E25: ALG1310 | F25: 4 | G25: AL012 | H25: Durrës | I25: assigned | J25: district to prefecture
A26: 2024 | B26: AL | C26: wnv-2024.html, Table 1 | D26: Elbasan | E26: ALG1311 | F26: 8 | G26: AL021 | H26: Elbasan | I26: assigned | J26: district to prefecture
A27: 2024 | B27: AL | C27: wnv-2024.html, Table 1 | D27: Fier | E27: ALG1312 | F27: 11 | G27: AL032 | H27: Fier | I27: assigned | J27: district to prefecture
A28: 2024 | B28: AL | C28: wnv-2024.html, Table 1 | D28: Kavaje | E28: ALG1316 | F28: 3 | G28: AL022 | H28: Tiranë | I28: assigned | J28: Kavajë sits in Tiranë county
A29: 2024 | B29: AL | C29: wnv-2024.html, Table 1 | D29: Kruje | E29: ALG1319 | F29: 1 | G29: AL012 | H29: Durrës | I29: assigned | J29: Krujë sits in Durrës county
A30: 2024 | B30: AL | C30: wnv-2024.html, Table 1 | D30: Kucove | E30: ALG1320 | F30: 4 | G30: AL031 | H30: Berat | I30: assigned | J30: Kuçovë sits in Berat county
A31: 2024 | B31: AL | C31: wnv-2024.html, Table 1 | D31: Kurbin | E31: ALG1322 | F31: 6 | G31: AL014 | H31: Lezhë | I31: assigned | J31: Kurbin sits in Lezhë county
A32: 2024 | B32: AL | C32: wnv-2024.html, Table 1 | D32: Lezhe | E32: ALG1323 | F32: 5 | G32: AL014 | H32: Lezhë | I32: assigned | J32: district to prefecture
A33: 2024 | B33: AL | C33: wnv-2024.html, Table 1 | D33: Lushnje | E33: ALG1325 | F33: 22 | G33: AL032 | H33: Fier | I33: assigned | J33: Lushnjë sits in Fier county
A34: 2024 | B34: AL | C34: wnv-2024.html, Table 1 | D34: Mallakaster | E34: ALG1327 | F34: 1 | G34: AL032 | H34: Fier | I34: assigned | J34: Mallakastër sits in Fier county
A35: 2024 | B35: AL | C35: wnv-2024.html, Table 1 | D35: Pogradec | E35: ALG1332 | F35: 1 | G35: AL034 | H35: Korcë | I35: assigned | J35: Pogradec sits in Korçë county
... A37: 2024 | B37: AL | C37: wnv-2024.html, Table 1 | D37: Vlore | E37: ALG1340 | F37: 11 | G37: AL035 | H37: Vlorë | I37: assigned | J37: district to prefecture
A38: 2013 | B38: BA | C38: Table of cases 2013 (HTML) | D38: Modrica canton | F38: 1 | I38: unresolved | J38: Modriča lies in Republika Srpska; entity, not a statistical region
A39: 2013 | B39: BA | C39: Table of cases 2013 (HTML) | D39: Tuzlansko-podrinjski canton | F39: 2 | I39: unresolved | J39: canton of the Federation
A40: 2014 | B40: BA | C40: Table of cases 2014 (HTML) | D40: Republika Srpska | F40: 13 | I40: unresolved | J40: entity-level report covering roughly half the country
E42: Cases in assembled file | F42: =SUMIFS(F2:F40,I2:I40,"<>unresolved") -> 154
...

Sheet Unit summary
A1: Country | B1: Unit | C1: Name | D1: Total cases | E1: First invasion year | F1: In assembled file
A2: AL | B2: AL011 | C2: Dibër | D2: =SUMIFS('Source rows'!$F$2:$F$40,'Source rows'!$G$2:$G$40,$B2) -> 0 | E2: =IF(D2=0,"never reported",_xlfn.MINIFS('Source rows'!$A$2:$A$40,'Source rows'!$G$2:$G$40,$B2,'Source rows'!$F$2:$F$40,">0")) -> never reported | F2: yes
A3: AL | B3: AL012 | C3: Durrës | D3: =SUMIFS('Source rows'!$F$2:$F$40,'Source rows'!$G$2:$G$40,$B3) -> 5 | E3: =IF(D3=0,"never reported",_xlfn.MINIFS('Source rows'!$A$2:$A$40,'Source rows'!$G$2:$G$40,$B3,'Source rows'!$F$2:$F$40,">0")) -> 2024 | F3: yes
A4: AL | B4: AL013 | C4: Kukës | D4: =SUMIFS('Source rows'!$F$2:$F$40,'Source rows'!$G$2:$G$40,$B4) -> 0 | E4: =IF(D4=0,"never reported",_xlfn.MINIFS('Source rows'!$A$2:$A$40,'Source rows'!$G$2:$G$40,$B4,'Source rows'!$F$2:$F$40,">0")) -> never reported | F4: yes
A5: AL | B5: AL014 | C5: Lezhë | D5: =SUMIFS('Source rows'!$F$2:$F$40,'Source rows'!$G$2:$G$40,$B5) -> 13 | E5: =IF(D5=0,"never reported",_xlfn.MINIFS('Source rows'!$A$2:$A$40,'Source rows'!$G$2:$G$40,$B5,'Source rows'!$F$2:$F$40,">0")) -> 2011 | F5: yes
A6: AL | B6: AL015 | C6: Shkodër | D6: =SUMIFS('Source rows'!$F$2:$F$40,'Source rows'!$G$2:$G$40,$B6) -> 0 | E6: =IF(D6=0,"never reported",_xlfn.MINIFS('Source rows'!$A$2:$A$40,'Source rows'!$G$2:$G$40,$B6,'Source rows'!$F$2:$F$40,">0")) -> never reported | F6: yes
A7: AL | B7: AL021 | C7: Elbasan | D7: =SUMIFS('Source rows'!$F$2:$F$40,'Source rows'!$G$2:$G$40,$B7) -> 8 | E7: =IF(D7=0,"never reported",_xlfn.MINIFS('Source rows'!$A$2:$A$40,'Source rows'!$G$2:$G$40,$B7,'Source rows'!$F$2:$F$40,">0")) -> 2024 | F7: yes
A8: AL | B8: AL022 | C8: Tiranë | D8: =SUMIFS('Source rows'!$F$2:$F$40,'Source rows'!$G$2:$G$40,$B8) -> 18 | E8: =IF(D8=0,"never reported",_xlfn.MINIFS('Source rows'!$A$2:$A$40,'Source rows'!$G$2:$G$40,$B8,'Source rows'!$F$2:$F$40,">0")) -> 2024 | F8: yes
A9: AL | B9: AL031 | C9: Berat | D9: =SUMIFS('Source rows'!$F$2:$F$40,'Source rows'!$G$2:$G$40,$B9) -> 18 | E9: =IF(D9=0,"never reported",_xlfn.MINIFS('Source rows'!$A$2:$A$40,'Source rows'!$G$2:$G$40,$B9,'Source rows'!$F$2:$F$40,">0")) -> 2024 | F9: yes
A10: AL | B10: AL032 | C10: Fier | D10: =SUMIFS('Source rows'!$F$2:$F$40,'Source rows'!$G$2:$G$40,$B10) -> 34 | E10: =IF(D10=0,"never reported",_xlfn.MINIFS('Source rows'!$A$2:$A$40,'Source rows'!$G$2:$G$40,$B10,'Source rows'!$F$2:$F$40,">0")) -> 2024 | F10: yes
A11: AL | B11: AL033 | C11: Gjirokastër | D11: =SUMIFS('Source rows'!$F$2:$F$40,'Source rows'!$G$2:$G$40,$B11) -> 0 | E11: =IF(D11=0,"never reported",_xlfn.MINIFS('Source rows'!$A$2:$A$40,'Source rows'!$G$2:$G$40,$B11,'Source rows'!$F$2:$F$40,">0")) -> never reported | F11: yes
A12: AL | B12: AL034 | C12: Korcë | D12: =SUMIFS('Source rows'!$F$2:$F$40,'Source rows'!$G$2:$G$40,$B12) -> 1 | E12: =IF(D12=0,"never reported",_xlfn.MINIFS('Source rows'!$A$2:$A$40,'Source rows'!$G$2:$G$40,$B12,'Source rows'!$F$2:$F$40,">0")) -> 2024 | F12: yes
A13: AL | B13: AL035 | C13: Vlorë | D13: =SUMIFS('Source rows'!$F$2:$F$40,'Source rows'!$G$2:$G$40,$B13) -> 11 | E13: =IF(D13=0,"never reported",_xlfn.MINIFS('Source rows'!$A$2:$A$40,'Source rows'!$G$2:$G$40,$B13,'Source rows'!$F$2:$F$40,">0")) -> 2024 | F13: yes
... A29: XK | B29: XK007 | C29: Gjakovë | D29: =SUMIFS('Source rows'!$F$2:$F$40,'Source rows'!$G$2:$G$40,$B29) -> 0 | E29: =IF(D29=0,"never reported",_xlfn.MINIFS('Source rows'!$A$2:$A$40,'Source rows'!$G$2:$G$40,$B29,'Source rows'!$F$2:$F$40,">0")) -> never reported | F29: yes
A31: Bosnia and Herzegovina is not listed: its 2013 and 2014 reports are at canton and entity level and do not resolve onto the three BA statistical regions in the project's files. 16 cases are held out pending your decision.
